Workbook
Name Project_Start: '2023 TM Planner '!#REF!
Name Project_Start: #REF!
Name Scrolling_Increment: '2023 TM Planner '!#REF!
Name Scrolling_Increment: #REF!
Name Today: TODAY()

Sheet 2023 TM Planner 
B2: 2023 Talent Management & Events Calendar
M4: Main Activity | T4: Sessions / Workshops | AG4: Communication
M6: 44866 | Q6: 44896 | U6: 44927 | Y6: 44958 | AC6: 44986 | AG6: 45017 | AK6: 45047 | AO6: 45078 | AS6: 45108 | AW6: 45139 | BA6: 45170 | BE6: 45200 | BI6: 45231 | BM6: 45261
M7: 1 | N7: 2 | O7: 3 | P7: 4 | Q7: 1 | R7: 2 | S7: 3 | T7: 4 | U7: 1 | V7: 2 | W7: 3 | X7: 4 | Y7: 1 | Z7: 2 | AA7: 3 | AB7: 4 | AC7: 1 | AD7: 2 | AE7: 3 | AF7: 4 | AG7: 1 | AH7: 2 | AI7: 3 | AJ7: 4 | AK7: 1 | AL7: 2 | AM7: 3 | AN7: 4 | AO7: 1 | AP7: 2 | AQ7: 3 | AR7: 4 | AS7: 1 | AT7: 2 | AU7: 3 | AV7: 4 | AW7: 1 | AX7: 2 | AY7: 3 | AZ7: 4 | BA7: 1 | BB7: 2 | BC7: 3 | BD7: 4 | BE7: 1 | BF7: 2 | BG7: 3 | BH7: 4 | BI7: 1 | BJ7: 2 | BK7: 3 | BL7: 4 | BM7: 5 | BN7: 6 | BO7: 7 | BP7: 8
B8: Objectives | C8: Activity | D8: Responsibility | H8: Expected Outcome | I8: Timelines
D9: TM | E9: HRBP | F9: Line Manager | G9: Employee | I9: Start | J9: End | K9: Days
B12: 2022 Year End Evaluation | C12: Confirmation on the 100% employees goal completion on the system | E12: 2 | H12: 100% completion | I12: 44880 | J12: 44895 | K12: =J12-I12 -> 15
C13: Corporate Communication & Release the form on the system | D13: 2 | I13: 44900 | J13: 44900 | K13: 1
C14: Enablement sessions for HRPBs | D14: 2 | I14: 44900 | J14: 44915 | K14: ='2023 TM Planner '!$J14-'2023 TM Planner '!$I14 -> 15
C15: Enablement sessions for Employees | D15: 2 | E15: 2 | I15: 44900 | J15: 44915 | K15: ='2023 TM Planner '!$J15-'2023 TM Planner '!$I15 -> 15
C16: Enablement sessions for Line managers | D16: 2 | E16: 2 | I16: 44928 | J16: 44946 | K16: ='2023 TM Planner '!$J16-'2023 TM Planner '!$I16 -> 18
C17: Complete the self-evaluation on the system | G17: 2 | I17: 44900 | J17: 44957 | K17: =J17-I17 -> 57
C18: complete the performance discussion with the employees | F18: 2 | G18: 2 | I18: 44896 | J18: 44957 | K18: =J18-I18 -> 61
C19: Complete the line manager rating on the system | F19: 2 | I19: 44896 | J19: 44957 | K19: =J19-I19 -> 61
B21: 2022 Calibration | C21: Enablement session HRBPs, LMs | D21: 2 | E21: 2 | H21: PRD Rating completion | I21: 44941 | J21: 44957 | K21: =J21-I21 -> 16
C22: Discussion meetings with the Line manager | E22: 2 | F22: 2 | I22: 44941 | J22: 44957 | K22: ='2023 TM Planner '!$J22-'2023 TM Planner '!$I22 -> 16
C23: Finalize Calibration meetings with the HODs | E23: 2 | I23: 44958 | J23: 44972 | K23: ='2023 TM Planner '!$J23-'2023 TM Planner '!$I23 -> 14
C24: LMs communicate the rating to employees | E24: 2 | F24: 2 | I24: 44972 | J24: 44985 | K24: ='2023 TM Planner '!$J24-'2023 TM Planner '!$I24 -> 13
C25: 2022 Calibration Rating Communication | D25: 2 | I25: 44986 | J25: 44986 | K25: 1
C26: Employees Appeal - Within 15 days of the rating communication | E26: 2 | G26: 2 | I26: 44987 | J26: 45008 | K26: ='2023 TM Planner '!$J26-'2023 TM Planner '!$I26 -> 21
B28: 2023 Individual Goal Setting | C28: Release the Form on the system | D28: 2 | H28: 100% goal setting completion | I28: 44928 | J28: 44928 | K28: =J28-I28 -> 0
C29: Corporate comms communication | D29: 2 | I29: 44949 | J29: 44956 | K29: ='2023 TM Planner '!$J29-'2023 TM Planner '!$I29 -> 7
C30: Enablement sessions & materials for Line managers | D30: 2 | E30: 2 | I30: 44952 | J30: 44967 | K30: ='2023 TM Planner '!$J30-'2023 TM Planner '!$I30 -> 15
C31: Enablement sessions for employees | D31: 2 | E31: 2 | F31: 2 | I31: 44952 | J31: 44972 | K31: ='2023 TM Planner '!$J31-'2023 TM Planner '!$I31 -> 20
C32: Line manager & employee objective-setting meetings | F32: 2 | G32: 2 | I32: 44928 | J32: 44985 | K32: =J32-I32 -> 57
C33: Completion of the goal settings on the system | G33: 2 | I33: 44928 | J33: 45000 | K33: ='2023 TM Planner '!$J33-'2023 TM Planner '!$I33 -> 72
B35: Critical Role Identification | C35: Review the critical role & highlight the ones included in the talent value exercise | E35: 2 | F35: 2 | H35: *Proactive Identification Based on Company Needs * Forecast and Plan for Change * Critical Roles to Future Business Needs | I35: 44972 | J35: 44985 | K35: =J35-I35 -> 13
B37: Talent Identification | C37: Talent identification initial meeting | D37: 2 | E37: 2 | F37: 2 | H37: * Building successor profiles * Assess development needs * Enabling employees Career path * Employees segment and satisfaction | I37: 44958 | J37: 44972 | K37: =J37-I37 -> 14
C38: Potential assessment by line manager | F38: 2 | G38: 2 | I38: 44958 | J38: 44972 | K38: =J38-I38 -> 14
C39: Collect employee data/ Submit Top talents list after consolidation | E39: 2 | F39: 2 | I39: 44972 | J39: 44985 | K39: =J39-I39 -> 13
C40: Top Talent Calibration (9 box performance) | E40: 2 | F40: 2 | I40: 44972 | J40: 44985 | K40: =J40-I40 -> 13
C41: Run external assessment for the top 3 talents | D41: 2 | E41: 2 | F41: 2 | G41: 2 | I41: 44986 | J41: 45016 | K41: =J41-I41 -> 30
C42: Talent Card - Band H+ | E42: 2 | F42: 2 | I42: 44986 | J42: 45016 | K42: =J42-I42 -> 30
C43: Download and map the data from the talent cards | E43: 2 | I43: 45017 | J43: 45023 | K43: =J43-I43 -> 6
C44: Anticipate vacancies for the next 12 month | E44: 2 | F44: 2 | I44: 45017 | J44: 45024 | K44: =J44-I44 -> 7
C45: Talent Discussion ( Identifying prioritized successors, Hi- Pos and candidate slate for new vacancies) | E45: 2 | F45: 2 | I45: 45024 | J45: 45046 | K45: =J45-I45 -> 22
C46: Action plan with all agreed points | E46: 2 | I46: 45024 | J46: 45046 | K46: =J46-I46 -> 22
C47: Top talent IDPs setting with employees | F47: 2 | G47: 2 | I47: 45047 | J47: 45077 | K47: =J47-I47 -> 30
C48: IDP Sign off meeting | F48: 2 | G48: 2 | I48: 45047 | J48: 45077 | K48: =J48-I48 -> 30
C49: Quarterly review and status update | E49: 2 | F49: 2 | G49: 2 | I49: Aug/ Nov 2023
...

Sheet 2023 Activity
