Workbook
Name Project_Start: '2023 PM & TM Activities '!#REF!
Name Project_Start: #REF!
Name Scrolling_Increment: '2023 PM & TM Activities '!#REF!
Name Scrolling_Increment: #REF!
Name Today: TODAY()

Sheet 2023 PM & TM Activities 
B2: PM & TM Activities - 2023
L4: Main Activity | S4: Sessions / Workshops | AF4: Communication
L6: 44866 | P6: 44896 | T6: 44927 | X6: 44958 | AB6: 44986 | AF6: 45017 | AJ6: 45047 | AN6: 45078 | AR6: 45108 | AV6: 45139 | AZ6: 45170 | BD6: 45200 | BH6: 45231 | BL6: 45261
L7: 1 | M7: 2 | N7: 3 | O7: 4 | P7: 1 | Q7: 2 | R7: 3 | S7: 4 | T7: 1 | U7: 2 | V7: 3 | W7: 4 | X7: 1 | Y7: 2 | Z7: 3 | AA7: 4 | AB7: 1 | AC7: 2 | AD7: 3 | AE7: 4 | AF7: 1 | AG7: 2 | AH7: 3 | AI7: 4 | AJ7: 1 | AK7: 2 | AL7: 3 | AM7: 4 | AN7: 1 | AO7: 2 | AP7: 3 | AQ7: 4 | AR7: 1 | AS7: 2 | AT7: 3 | AU7: 4 | AV7: 1 | AW7: 2 | AX7: 3 | AY7: 4 | AZ7: 1 | BA7: 2 | BB7: 3 | BC7: 4 | BD7: 1 | BE7: 2 | BF7: 3 | BG7: 4 | BH7: 1 | BI7: 2 | BJ7: 3 | BK7: 4 | BL7: 5 | BM7: 6 | BN7: 7 | BO7: 8
B8: Objectives | C8: Activity | D8: Responsibility | H8: KPIs | I8: Timelines
D9: TM | E9: HRBP | F9: Line Manager | G9: Employee | I9: Start | J9: End | K9: Days
B12: 2022 Year End Evaluation | C12: Corporate Communication & Release the form on the system | D12: 2 | I12: 44900 | J12: 44900 | K12: 1
C13: Enablement sessions for HRPBs | D13: 2 | I13: 44900 | J13: 44915 | K13: ='2023 PM & TM Activities '!$J13-'2023 PM & TM Activities '!$I13 -> 15
C14: Enablement sessions for Employees | D14: 2 | E14: 2 | I14: 44900 | J14: 44915 | K14: ='2023 PM & TM Activities '!$J14-'2023 PM & TM Activities '!$I14 -> 15
C15: Enablement sessions for Line managers | D15: 2 | E15: 2 | I15: 44928 | J15: 44946 | K15: ='2023 PM & TM Activities '!$J15-'2023 PM & TM Activities '!$I15 -> 18
C16: Complete the self-evaluation on the system | G16: 2 | I16: 44900 | J16: 44957 | K16: =J16-I16 -> 57
C17: complete the performance discussion with the employees | F17: 2 | G17: 2 | I17: 44896 | J17: 44957 | K17: =J17-I17 -> 61
C18: Complete the line manager rating on the system | F18: 2 | I18: 44896 | J18: 44957 | K18: =J18-I18 -> 61
B20: 2022 Calibration | C20: Enablement session HRBPs, LMs | D20: 2 | E20: 2 | H20: 100% completion | I20: 44941 | J20: 44957 | K20: =J20-I20 -> 16
C21: Calibration meetings with the Line manager | E21: 2 | F21: 2 | I21: 44941 | J21: 44957 | K21: ='2023 PM & TM Activities '!$J21-'2023 PM & TM Activities '!$I21 -> 16
C22: Finalize Calibration meetings with the HODs | E22: 2 | I22: 44958 | J22: 44972 | K22: ='2023 PM & TM Activities '!$J22-'2023 PM & TM Activities '!$I22 -> 14
C23: 2022 Calibration Rating Communication | D23: 2 | I23: 44986 | J23: 44986 | K23: 1
C24: Employees Appeal - Within 5 days of the rating communication | E24: 2 | G24: 2 | I24: 44987 | J24: 45008 | K24: ='2023 PM & TM Activities '!$J24-'2023 PM & TM Activities '!$I24 -> 21
B26: 2023 Goal Setting | C26: Release the Form on the system | D26: 2 | H26: 95% completion | I26: 44928 | J26: 44928 | K26: =J26-I26 -> 0
C27: Corporate comms communication | D27: 2 | I27: 44949 | J27: 44956 | K27: ='2023 PM & TM Activities '!$J27-'2023 PM & TM Activities '!$I27 -> 7
C28: Enablement sessions & materials for Line managers | D28: 2 | E28: 2 | I28: 44952 | J28: 44967 | K28: ='2023 PM & TM Activities '!$J28-'2023 PM & TM Activities '!$I28 -> 15
C29: Enablement sessions for employees | D29: 2 | E29: 2 | F29: 2 | I29: 44952 | J29: 44972 | K29: ='2023 PM & TM Activities '!$J29-'2023 PM & TM Activities '!$I29 -> 20
C30: Conduct Goal-setting workshops | D30: 2 | E30: 2 | F30: 2 | I30: 44928 | J30: 44985 | K30: =J30-I30 -> 57
C31: Completion of the goal settings on the system | G31: 2 | I31: 44928 | J31: 45000 | K31: ='2023 PM & TM Activities '!$J31-'2023 PM & TM Activities '!$I31 -> 72
C32: Goal Audit for 5 % of the Population | D32: 2 | I32: 45047 | J32: 45078 | K32: ='2023 PM & TM Activities '!$J32-'2023 PM & TM Activities '!$I32 -> 31
B34: Critical Role Identification | C34: Review the critical role & share updated with TM | E34: 2 | F34: 2 | H34: * Critical Roles to Future Business Needs | I34: 44972 | J34: 44985 | K34: =J34-I34 -> 13
B36: Talent Identification | C36: Talent Planning Kick off | D36: 2 | E36: 2 | F36: 2 | H36: * Building successor profiles * Assess development needs * Enabling employees Career path * Employees segment and satisfaction | I36: 45078 | J36: 45108 | K36: =J36-I36 -> 30
C37: Configuring the Talent Module on Igrow | D37: 2 | I37: 44958 | J37: 45047 | K37: =J37-I37 -> 89
C38: Update data on the tool | D38: 2 | E38: 2 | I38: 45078 | J38: 45108 | K38: =J38-I38 -> 30
C39: Enablemnt session for HRBPs & Line managers | D39: 2 | E39: 2 | F39: 2 | I39: 45078 | J39: 45108 | K39: =J39-I39 -> 30
C40: Update employees talent cards | E40: 2 | F40: 2 | G40: 2 | I40: 44986 | J40: 45016 | K40: =J40-I40 -> 30
C41: Talent Planning Meetings | E41: 2 | F41: 2 | I41: 45108 | J41: 45170 | K41: =J41-I41 -> 62
C42: Quarterly review and status update | E42: 2 | F42: 2 | G42: 2 | I42: Aug/ Nov 2023
B44: Continuous Performance Management | C44: Release Communcation for CPM | D44: 2 | F44: 2 | G44: 2 | H44: Ensure 80 % Utilization of CPM | I44: June - Nov
C45: Leverage the Intranet & Microtips | D45: 2 | E45: 2
C46: Develiver Enabelment session on Continous Conversation & how to use CPM | D46: 2 | E46: 2
C47: CPM Simulation Utilization | D47: 2 | E47: 2
C48: Reporting to TM Leads | D48: 2 | E48: 2
B50: 360 Leadership Assessment | C50: Roll out the 360 Leadership assessment | D50: 2 | E50: 2 | H50: 100% of band G/H people managers enrolled in Emerging Leader program with 360 completed
B52: Career Growth & IDP | C52: e-mail communication to roll out the career growth & IDP | D52: 2 | I52: 45047 | J52: 45061 | K52: =J52-I52 -> 14
...

Sheet 2023 PM & TM Calendar
